<mujoco model="Humanoid">
  <option timestep="0.005"/>
  <compiler angle="radian" meshdir="kortex_description/arms_with_gripper/gen3_7dof_with_L31K/meshes/" autolimits="true"/>

  <asset>
    <!-- <texture type="skybox" builtin="gradient" rgb1=".3 .5 .7" rgb2="0 0 0" width="32" height="512"/> -->
    <texture name="body" type="cube" builtin="flat" mark="cross" width="128" height="128" rgb1="0.8 0.6 0.4" rgb2="0.8 0.6 0.4" markrgb="1 1 1" random="0.01"/>
    <material name="body" texture="body" texuniform="true" rgba="0.8 0.6 .4 1"/>
    <!-- <texture name="grid" type="2d" builtin="checker" width="512" height="512" rgb1=".1 .2 .3" rgb2=".2 .3 .4"/>
    <material name="grid" texture="grid" texrepeat="1 1" texuniform="true" reflectance=".2"/> -->
    <mesh name="base_link" file="base_link.STL"/>
    <mesh name="shoulder_link" file="shoulder_link.STL"/>
    <mesh name="half_arm_1_link" file="half_arm_1_link.STL"/>
    <mesh name="half_arm_2_link" file="half_arm_2_link.STL"/>
    <mesh name="forearm_link" file="forearm_link.STL"/>
    <mesh name="spherical_wrist_1_link" file="spherical_wrist_1_link.STL"/>
    <mesh name="spherical_wrist_2_link" file="spherical_wrist_2_link.STL"/>
    <mesh name="bracelet_with_vision_link" file="bracelet_with_vision_link.STL"/>
    <mesh name="gripper_base_link" file="gripper_base_link.STL"/>
    <mesh name="right_finger_prox_link" file="right_finger_prox_link.STL"/>
    <mesh name="right_finger_dist_link" file="right_finger_dist_link.STL"/>
    <mesh name="left_finger_prox_link" file="left_finger_prox_link.STL"/>
    <mesh name="left_finger_dist_link" file="left_finger_dist_link.STL"/>
  </asset>

  <default>
    <!-- Kinova gen3 -->
    <default class="kinova_gen3">
      <joint pos="0 0 0" axis="0 0 1" damping="0.2"/>
      <motor ctrllimited="false" forcelimited="true" />
    </default>
    <!-- <motor ctrlrange="-1 1" ctrllimited="true"/> -->
    <default class="body">
      <!-- geoms -->
      <geom type="capsule" condim="1" friction=".7" solimp=".9 .99 .003" solref=".015 1" material="body" group="1"/>
      <default class="lift">
        <geom fromto="0 0 0 0 0 2" size=".01"/>
      </default>
      <default class="thigh">
        <geom size=".06"/>
      </default>
      <default class="shin">
        <geom fromto="0 0 0 0 0 -.3"  size=".049"/>
      </default>
      <default class="foot">
        <geom size=".027"/>
        <default class="foot1">
          <geom fromto="-.07 -.01 0 .14 -.03 0"/>
        </default>
        <default class="foot2">
          <geom fromto="-.07 .01 0 .14  .03 0"/>
        </default>
      </default>
      <default class="arm_upper">
        <geom size=".04"/>
      </default>
      <default class="arm_lower">
        <geom size=".031"/>
      </default>
      <default class="hand">
        <geom type="sphere" size=".04"/>
      </default>

      <!-- joints -->
      <!-- <joint type="hinge" damping=".2" stiffness="1" armature=".01" limited="true" solimplimit="0 .99 .01"/> -->
      <general gaintype="fixed" biastype="affine" ctrlrange="-6.2831 6.2831" gainprm="2000" biasprm="0 -2000 -400"
        forcerange="-390 390"/>
      <default class="liftjoint">
        <joint type="slide" axis="0 0 1" stiffness="300" damping="500"/>
        <general ctrlrange="-.3 1.8" gainprm="300" biasprm="0 -300 -50" forcerange="-1000 1000"/>
      </default>
      <default class="hip_y">
        <joint axis="0 1 0" range="-150 20"/>
        <general gainprm="500" biasprm="0 -500 -100" forcerange="-90 90" ctrlrange="-10 20"/>
      </default>
      <default class="knee">
        <joint pos="0 0 .02" axis="0 -1 0" range="-160 2"/>
        <general gainprm="500" biasprm="0 -500 -100" forcerange="-90 90" ctrlrange="-10 20"/>
      </default>
      <default class="shoulder">
        <joint range="-4.25 3" stiffness="100" damping="400"/>
        <general ctrlrange="-4.25 3"/>
      </default>
      <default class="elbow">
        <joint range="-2.5 1.25" stiffness="100" damping="400"/>
        <general ctrlrange="-2.5 1.25"/>
      </default>
    </default>
  </default>

  <worldbody>
    <body name= "bodylift" pos = "0 0 0" childclass = "body">
      <geom name = "lift" fromto="0 0 0 0 0 0.9" size=".01"  rgba = "1 0 0 0"/>
      <body name="torso" pos="-.1 0 1.202">
        <joint name="body_lift" axis="0 0 1"  class="liftjoint"/>
        <geom name="torso" fromto="0 -.07 0 0 .07 0" size=".07"/>
        <geom name="waist_upper" fromto="-.01 -.06 -.12 -.01 .06 -.12" size=".06"/>
        <body name="head" pos="0 0 .19">
          <geom name="head" type="sphere" size=".09"/>
          <camera name="egocentric" pos=".09 0 0" xyaxes="0 -1 0 .1 0 1" fovy="80"/>
        </body>
        <body name="waist_lower" pos="-.01 0 -.24">
          <geom name="waist_lower" fromto="0 -.06 0 0 .06 0" size=".055"/>
          <body name="pelvis" pos="0 0 -.105">
            <geom name="butt" fromto="-.02 -.07 0 -.02 .07 0" size=".09"/>
            <body name="thigh_right" pos="0 -.1 -.04">
              <joint name="hip_y_right" class="hip_y"/>
              <geom name="thigh_right" fromto="0 0 0 0 .01 -.34" class="thigh"/>
              <body name="shin_right" pos="0 .01 -.4">
                <joint name="knee_right" class="knee"/>
                <geom name="shin_right" class="shin"/>
              </body>
            </body>
            <body name="thigh_left" pos="0 .1 -.04">
              <joint name="hip_y_left" class="hip_y"/>
              <geom name="thigh_left" fromto="0 0 0 0 -.01 -.34" class="thigh"/>
              <body name="shin_left" pos="0 -.01 -.4">
                <joint name="knee_left" class="knee"/>
                <geom name="shin_left" fromto="0 0 0 0 0 -.3" class="shin"/>
              </body>
            </body>
          </body>
        </body>
        <body name="upper_arm_right" pos="0 -.17 .06">
          <joint name="shoulder1_right" axis="2 1 1"  class="shoulder"/>
          <joint name="shoulder2_right" axis="0 -1 1" class="shoulder"/>
          <geom name="upper_arm_right" fromto="0 0 0 .16 -.16 -.16" class="arm_upper" contype="0" conaffinity="0"/>
          <body name="lower_arm_right" pos=".18 -.18 -.18">
            <joint name="elbow_right" axis="0 -1 1" class="elbow"/>
            <geom name="lower_arm_right" fromto=".01 .01 .01 .17 .17 .17" class="arm_lower" contype="0" conaffinity="0"/>
            <body name="hand_right" pos=".18 .18 .18">
              <geom name="hand_right" zaxis="1 1 1" class="hand" contype="0" conaffinity="0"  />
              <site name="hand_site_r" pos="0 0 0" size="0.02" rgba="0 1 0 1"/>
            </body>
          </body>
        </body>
        <body name="upper_arm_left" pos="0 .17 .06">
          <joint name="shoulder1_left" axis="-2 1 -1" class="shoulder"/>
          <joint name="shoulder2_left" axis="0 -1 -1"  class="shoulder"/>
          <geom name="upper_arm_left" fromto="0 0 0 .16 .16 -.16" class="arm_upper" contype="0" conaffinity="0"/>
          <body name="lower_arm_left" pos=".18 .18 -.18">
            <joint name="elbow_left" axis="0 -1 -1" class="elbow"/>
            <geom name="lower_arm_left" fromto=".01 -.01 .01 .17 -.17 .17" class="arm_lower" contype="0" conaffinity="0"/>
            <body name="hand_left" pos=".18 -.18 .18">
              <geom name="hand_left" zaxis="1 -1 1" class="hand" contype="0" conaffinity="0"  />
              <site name="hand_site_l" pos="0 0 0" size="0.02" rgba="0 1 0 1"/>
            </body>
          </body>
        </body>
        <body name = "bag">
            <geom type="box" pos="-0.1 0 -0.1" size="0.01 0.15 0.1" rgba="1 1 1 1"/>
            <geom type="box" pos="-0.17 -0.06 -0.12" size="0.08 0.09 0.01" quat="0.92388 0.38268 0 0" rgba="1 1 1 1"/>
            <geom type="box" pos="-0.17 0.06 -0.12" size="0.08 0.09 0.01" quat="0.92388 -0.38268 0 0" rgba="1 1 1 1"/>
            <!-- <geom type="box" pos="-0.17 0 -0.2" size="0.08 0.15 0.01" rgba="1 1 1 1"/> -->
            <body name="base_link" pos="-0.19 -0.06 -0.11" quat="0.9238795325112867 0.3826834323650898 0 0" childclass="kinova_gen3">
              <geom type="mesh" group="1"  rgba="0.75294 0.75294 0.75294 1"  mesh="base_link"/>
              <site name="main_site" pos="0 0 0" size="0.02" rgba="0 1 0 1"/>
              <body name="shoulder_link" pos="0 0 0.15643" quat="0 1 0 0">
                <inertial pos="-2.3e-05 -0.010364 -0.07336" quat="0.707051 0.0451246 -0.0453544 0.704263" 
                  mass="1.3773" diaginertia="0.00488868 0.00457 0.00135132"/>
                <joint name="ACTUATOR1"  pos="0 0 0" axis="0 0 1" limited="false"/>
                <geom type="mesh" group="1" rgba="0.75294 0.75294 0.75294 1"  mesh="shoulder_link"/>
                <body name="half_arm_1_link" pos="0 0.005375 -0.12838" quat="0.707105 0.707108 0 0">
                  <inertial pos="-4.4e-05 -0.09958 -0.013278" quat="0.482348 0.516286 -0.516862 0.483366" 
                    mass="1.1636" diaginertia="0.0113017 0.011088 0.00102532"/>
                  <joint name="ACTUATOR2" pos="0 0 0" axis="0 0 1" limited="true" range="-2.25 2.25"/>
                  <geom type="mesh" group="1" rgba="0.75294 0.75294 0.75294 1" mesh="half_arm_1_link"/>
                  <body name="half_arm_2_link" pos="0 -0.21038 -0.006375" quat="0.707105 -0.707108 0 0">
                    <inertial pos="-4.4e-05 -0.006641 -0.117892" quat="0.706144 0.0213722 -0.0209128 0.707437" 
                      mass="1.1636" diaginertia="0.0111633 0.010932 0.00100671"/>
                    <joint name="ACTUATOR3" pos="0 0 0" axis="0 0 1" limited="false"/>
                    <geom type="mesh" group="1" rgba="0.75294 0.75294 0.75294 1" mesh="half_arm_2_link"/>
                    <body name="forearm_link" pos="0 0.006375 -0.21038" quat="0.707105 0.707108 0 0">
                      <inertial pos="-1.8e-05 -0.075478 -0.015006" quat="0.483678 0.515961 -0.515859 0.483455" 
                        mass="0.9302" diaginertia="0.00834839 0.008147 0.000598606"/>
                      <joint name="ACTUATOR4" pos="0 0 0" axis="0 0 1" limited="true" range="-2.58 2.58"/>
                      <geom type="mesh" group="1" rgba="0.75294 0.75294 0.75294 1" mesh="forearm_link"/>
                      <body name="spherical_wrist_1_link" pos="0 -0.20843 -0.006375" quat="0.707105 -0.707108 0 0">
                        <inertial pos="1e-06 -0.009432 -0.063883" quat="0.703558 0.0707492 -0.0707492 0.703558" 
                          mass="0.6781" diaginertia="0.00165901 0.001596 0.000346988"/>
                        <joint name="ACTUATOR5" pos="0 0 0" axis="0 0 1" limited="false"/>
                        <geom type="mesh" group="1" rgba="0.75294 0.75294 0.75294 1" mesh="spherical_wrist_1_link"/>
                        <body name="spherical_wrist_2_link" pos="0 0.00017505 -0.10593" quat="0.707105 0.707108 0 0">
                          <inertial pos="1e-06 -0.045483 -0.00965" quat="0.44426 0.550121 -0.550121 0.44426" 
                            mass="0.6781" diaginertia="0.00170087 0.001641 0.00035013"/>
                          <joint name="ACTUATOR6" pos="0 0 0" axis="0 0 1" limited="true" range="-2.1 2.1"/>
                          <geom type="mesh" group="1" rgba="0.75294 0.75294 0.75294 1" mesh="spherical_wrist_2_link"/>
                          <body name="bracelet_with_vision_link" pos="0 -0.10593 -0.00017505" quat="0.707105 -0.707108 0 0">
                            <site name="m_tip_site" pos="0 0 -0.22" size="0.01" rgba="0 1 0 0"/>
                            <inertial pos="-0.000218882 -0.00891946 -0.0457344" quat="0.974998 0.221623 -0.00610901 0.0150095" 
                              mass="0.6401" diaginertia="0.00130083 0.00115566 0.000620052"/>
                            <joint name="ACTUATOR7" pos="0 0 0" axis="0 0 1" limited="false"/>
                            <geom type="mesh" group="1" rgba="0.75294 0.75294 0.75294 1" mesh="bracelet_with_vision_link"/>
                            <geom pos="0 0 -0.061525" quat="0 1 0 0" type="mesh" group="1" mesh="gripper_base_link"/>
                            <body name="right_finger_prox_link" pos="0 0.030501 -0.131528" quat="0 0.707105 0 0.707108">
                              <inertial pos="0.020257 0.0063483 6.991e-05" quat="0.598941 0.598941 0.375858 0.375858" 
                                mass="0.018385" diaginertia="5.25068e-06 4.77e-06 1.59932e-06"/>
                              <joint name="EEF_JOINT_RB" pos="0 0 0" axis="0 0 1" limited="true" range="-0.09 0.96"/>
                              <geom type="mesh" group="1" mesh="right_finger_prox_link"/>
                              <body name="right_finger_dist_link" pos="-0.045636 0.020423 0">
                                <inertial pos="0.018488 0.0011091 0" quat="0.557345 0.557345 0.435162 0.435162" 
                                  mass="0.010748" diaginertia="1.91e-06 1.61e-06 5.5e-07"/>
                                <joint name="EEF_JOINT_RU" pos="0 0 0" axis="0 0 1" limited="true" range="-1.03 0.21"/>
                                <geom type="mesh" group="1" mesh="right_finger_dist_link"/>
                              </body>
                            </body>
                            <body name="left_finger_prox_link" pos="0 -0.0305 -0.131528" quat="0 0.707105 0 0.707108">
                              <inertial pos="0.020257 0.0063483 6.99e-05" quat="0.598941 0.598941 0.375858 0.375858" 
                                mass="0.018385" diaginertia="5.25068e-06 4.77e-06 1.59932e-06"/>
                              <joint name="EEF_JOINT_LB" pos="0 0 0" axis="0 0 1" limited="true" range="-0.96 0.09"/>
                              <geom type="mesh" group="1" mesh="left_finger_prox_link"/>
                              <body name="left_finger_dist_link" pos="-0.045636 -0.020423 6.9901e-05">
                                <inertial pos="-0.018488 0.0011091 0" quat="0.557345 0.557345 0.435162 0.435162" 
                                  mass="0.010748" diaginertia="1.91e-06 1.61e-06 5.5e-07"/>
                                <joint name="EEF_JOINT_LU" pos="0 0 0" axis="0 0 -1" limited="true" range="-0.21 1.03"/>
                                <geom type="mesh" group="1" mesh="left_finger_dist_link"/>
                              </body>
                            </body>
                          </body>
                        </body>
                      </body>
                    </body>
                  </body>
                </body>
              </body>
            </body>

            <body name="base_link2" pos="-0.19 0.06 -0.11" quat="0.9238795325112867 -0.3826834323650898 0 0" childclass="kinova_gen3">
              <geom type="mesh" group="1"  rgba="0.75294 0.75294 0.75294 1"  mesh="base_link"/>
              <site name="slave_site" pos="0 0 0" size="0.02" rgba="0 1 0 1"/>
              <body name="shoulder_link_2" pos="0 0 0.15643" quat="0 1 0 0">
                <inertial pos="-2.3e-05 -0.010364 -0.07336" quat="0.707051 0.0451246 -0.0453544 0.704263" 
                  mass="1.3773" diaginertia="0.00488868 0.00457 0.00135132"/>
                <joint name="ACTUATOR1_2" pos="0 0 0" axis="0 0 1" limited="false"/>
                <geom type="mesh" group="1" rgba="0.75294 0.75294 0.75294 1"  mesh="shoulder_link"/>
                <body name="half_arm_1_link_2" pos="0 0.005375 -0.12838" quat="0.707105 0.707108 0 0">
                  <inertial pos="-4.4e-05 -0.09958 -0.013278" quat="0.482348 0.516286 -0.516862 0.483366" 
                    mass="1.1636" diaginertia="0.0113017 0.011088 0.00102532"/>
                  <joint name="ACTUATOR2_2" pos="0 0 0" axis="0 0 1" limited="true" range="-2.41 2.41"/>
                  <geom type="mesh" group="1" rgba="0.75294 0.75294 0.75294 1" mesh="half_arm_1_link"/>
                  <body name="half_arm_2_link_2" pos="0 -0.21038 -0.006375" quat="0.707105 -0.707108 0 0">
                    <inertial pos="-4.4e-05 -0.006641 -0.117892" quat="0.706144 0.0213722 -0.0209128 0.707437" 
                      mass="1.1636" diaginertia="0.0111633 0.010932 0.00100671"/>
                    <joint name="ACTUATOR3_2" pos="0 0 0" axis="0 0 1" limited="false"/>
                    <geom type="mesh" group="1" rgba="0.75294 0.75294 0.75294 1" mesh="half_arm_2_link"/>
                    <body name="forearm_link_2" pos="0 0.006375 -0.21038" quat="0.707105 0.707108 0 0">
                      <inertial pos="-1.8e-05 -0.075478 -0.015006" quat="0.483678 0.515961 -0.515859 0.483455" 
                        mass="0.9302" diaginertia="0.00834839 0.008147 0.000598606"/>
                      <joint name="ACTUATOR4_2" pos="0 0 0" axis="0 0 1" limited="true" range="-2.66 2.66"/>
                      <geom type="mesh" group="1" rgba="0.75294 0.75294 0.75294 1" mesh="forearm_link"/>
                      <body name="spherical_wrist_1_link_2" pos="0 -0.20843 -0.006375" quat="0.707105 -0.707108 0 0">
                        <inertial pos="1e-06 -0.009432 -0.063883" quat="0.703558 0.0707492 -0.0707492 0.703558" 
                          mass="0.6781" diaginertia="0.00165901 0.001596 0.000346988"/>
                        <joint name="ACTUATOR5_2" pos="0 0 0" axis="0 0 1" limited="false"/>
                        <geom type="mesh" group="1" rgba="0.75294 0.75294 0.75294 1" mesh="spherical_wrist_1_link"/>
                        <body name="spherical_wrist_2_link_2" pos="0 0.00017505 -0.10593" quat="0.707105 0.707108 0 0">
                          <inertial pos="1e-06 -0.045483 -0.00965" quat="0.44426 0.550121 -0.550121 0.44426" 
                            mass="0.6781" diaginertia="0.00170087 0.001641 0.00035013"/>
                          <joint name="ACTUATOR6_2" pos="0 0 0" axis="0 0 1" limited="true" range="-2.23 2.23"/>
                          <geom type="mesh" group="1" rgba="0.75294 0.75294 0.75294 1" mesh="spherical_wrist_2_link"/>
                          <body name="bracelet_with_vision_link_2" pos="0 -0.10593 -0.00017505" quat="0.707105 -0.707108 0 0">
                            <site name="s_tip_site" pos="0 0 -0.22" size="0.01" rgba="0 1 0 0"/>
                            <inertial pos="-0.000218882 -0.00891946 -0.0457344" quat="0.974998 0.221623 -0.00610901 0.0150095" 
                              mass="0.6401" diaginertia="0.00130083 0.00115566 0.000620052"/>
                            <joint name="ACTUATOR7_2" pos="0 0 0" axis="0 0 1" limited="false"/>
                            <geom type="mesh" group="1" rgba="0.75294 0.75294 0.75294 1" mesh="bracelet_with_vision_link"/>
                            <geom pos="0 0 -0.061525" quat="0 1 0 0" type="mesh" group="1" mesh="gripper_base_link"/>
                            <body name="right_finger_prox_link_2" pos="0 0.030501 -0.131528" quat="0 0.707105 0 0.707108">
                              <inertial pos="0.020257 0.0063483 6.991e-05" quat="0.598941 0.598941 0.375858 0.375858" 
                                mass="0.018385" diaginertia="5.25068e-06 4.77e-06 1.59932e-06"/>
                              <joint name="EEF_JOINT_RB_2" pos="0 0 0" axis="0 0 1" limited="true" range="-0.09 0.96"/>
                              <geom type="mesh" group="1" mesh="right_finger_prox_link"/>
                              <body name="right_finger_dist_link_2" pos="-0.045636 0.020423 0">
                                <inertial pos="0.018488 0.0011091 0" quat="0.557345 0.557345 0.435162 0.435162" 
                                  mass="0.010748" diaginertia="1.91e-06 1.61e-06 5.5e-07"/>
                                <joint name="EEF_JOINT_RU_2" pos="0 0 0" axis="0 0 1" limited="true" range="-1.03 0.21"/>
                                <geom type="mesh" group="1" mesh="right_finger_dist_link"/>
                              </body>
                            </body>
                            <body name="left_finger_prox_link_2" pos="0 -0.0305 -0.131528" quat="0 0.707105 0 0.707108">
                              <inertial pos="0.020257 0.0063483 6.99e-05" quat="0.598941 0.598941 0.375858 0.375858" 
                                mass="0.018385" diaginertia="5.25068e-06 4.77e-06 1.59932e-06"/>
                              <joint name="EEF_JOINT_LB_2" pos="0 0 0" axis="0 0 1" limited="true" range="-0.96 0.09"/>
                              <geom type="mesh" group="1" mesh="left_finger_prox_link"/>
                              <body name="left_finger_dist_link_2" pos="-0.045636 -0.020423 6.9901e-05">
                                
                                <inertial pos="-0.018488 0.0011091 0" quat="0.557345 0.557345 0.435162 0.435162" 
                                  mass="0.010748" diaginertia="1.91e-06 1.61e-06 5.5e-07"/>
                                <joint name="EEF_JOINT_LU_2" pos="0 0 0" axis="0 0 -1" limited="true" range="-0.21 1.03"/>
                                <geom type="mesh" group="1" mesh="left_finger_dist_link"/>
                              </body>
                            </body>
                          </body>
                        </body>
                      </body>
                    </body>
                  </body>
                </body>
              </body>
            </body>
        </body>
      </body>
    </body>
  </worldbody>

  <equality>
    <joint joint1="hip_y_left" joint2="hip_y_right" polycoef="0 1 0 0 0"/>
    <joint joint1="knee_left" joint2="knee_right" polycoef="0 1 0 0 0"/>
    
    <joint joint1="hip_y_right" joint2="body_lift" polycoef="0 2.5 0 0 0"/>
    <joint joint1="knee_right" joint2="hip_y_right" polycoef="0 2.8 0.7 0 0"/>
    

    <joint joint1="EEF_JOINT_RB" joint2="EEF_JOINT_LB" polycoef="0 -1 0 0 0"/>
    <joint joint1="EEF_JOINT_LU" joint2="EEF_JOINT_LB" polycoef="0 1.3 0 0 0"/>
    <joint joint1="EEF_JOINT_RU" joint2="EEF_JOINT_LB" polycoef="0 0.8 0 0 0"/>

    <joint joint1="EEF_JOINT_RB_2" joint2="EEF_JOINT_LB_2" polycoef="0 -1 0 0 0"/>
    <joint joint1="EEF_JOINT_LU_2" joint2="EEF_JOINT_LB_2" polycoef="0 1.3 0 0 0"/>
    <joint joint1="EEF_JOINT_RU_2" joint2="EEF_JOINT_LB_2" polycoef="0 0.8 0 0 0"/>
  </equality>

  <actuator>
    <general class="liftjoint"         name="body_lift"              joint="body_lift"/>
    <general class="shoulder"          name="shoulder_right_axis"    joint="shoulder1_right"/>
    <general class="shoulder"          name="shoulder_right_axis2"   joint="shoulder2_right"/>
    <general class="elbow"             name="elbow_right"            joint="elbow_right"/>
    <general class="shoulder"          name="shoulder_left_axis"     joint="shoulder1_left"/>
    <general class="shoulder"          name="shoulder_left_axis2"    joint="shoulder2_left"/>
    <general class="elbow"             name="elbow_left"             joint="elbow_left"/>

    <!-- <general class="ctrl1"           name="ACTUATOR1_motor"      joint="ACTUATOR1"/>
    <general class="ctrl1_limited"   name="ACTUATOR2_motor"      joint="ACTUATOR2"/>
    <general class="ctrl2"           name="ACTUATOR3_motor"      joint="ACTUATOR3"/>
    <general class="ctrl2_limited"   name="ACTUATOR4_motor"      joint="ACTUATOR4"/>
    <general class="ctrl3"           name="ACTUATOR5_motor"      joint="ACTUATOR5"/>
    <general class="ctrl3_limited"   name="ACTUATOR6_motor"      joint="ACTUATOR6"/>
    <general class="ctrl4"           name="ACTUATOR7_motor"      joint="ACTUATOR7"/> -->

    <motor name="ACTUATOR1_motor" joint="ACTUATOR1" forcerange="-39 39"/>
    <motor name="ACTUATOR2_motor" joint="ACTUATOR2" forcerange="-39 39"/>
    <motor name="ACTUATOR3_motor" joint="ACTUATOR3" forcerange="-39 39"/>
    <motor name="ACTUATOR4_motor" joint="ACTUATOR4" forcerange="-39 39"/>
    <motor name="ACTUATOR5_motor" joint="ACTUATOR5" forcerange="-9 9"/>
    <motor name="ACTUATOR6_motor" joint="ACTUATOR6" forcerange="-9 9"/>
    <motor name="ACTUATOR7_motor" joint="ACTUATOR7" forcerange="-9 9"/>
    <motor name="EEF_JOINT_LB_motor" joint="EEF_JOINT_LB" forcerange="-3 3"/>

    <!-- <general class="ctrl1"           name="ACTUATOR1_motor_2"    joint="ACTUATOR1_2"/>
    <general class="ctrl1_limited"   name="ACTUATOR2_motor_2"    joint="ACTUATOR2_2"/>
    <general class="ctrl2"           name="ACTUATOR3_motor_2"    joint="ACTUATOR3_2"/>
    <general class="ctrl2_limited"   name="ACTUATOR4_motor_2"    joint="ACTUATOR4_2"/>
    <general class="ctrl3"           name="ACTUATOR5_motor_2"    joint="ACTUATOR5_2"/>
    <general class="ctrl3_limited"   name="ACTUATOR6_motor_2"    joint="ACTUATOR6_2"/>
    <general class="ctrl4"           name="ACTUATOR7_motor_2"    joint="ACTUATOR7_2"/> -->

    <motor name="ACTUATOR1_motor_2" joint="ACTUATOR1_2" forcerange="-39 39"/>
    <motor name="ACTUATOR2_motor_2" joint="ACTUATOR2_2" forcerange="-39 39"/>
    <motor name="ACTUATOR3_motor_2" joint="ACTUATOR3_2" forcerange="-39 39"/>
    <motor name="ACTUATOR4_motor_2" joint="ACTUATOR4_2" forcerange="-39 39"/>
    <motor name="ACTUATOR5_motor_2" joint="ACTUATOR5_2" forcerange="-9 9"/>
    <motor name="ACTUATOR6_motor_2" joint="ACTUATOR6_2" forcerange="-9 9"/>
    <motor name="ACTUATOR7_motor_2" joint="ACTUATOR7_2" forcerange="-9 9"/>
    <motor name="EEF_JOINT_LB_motor_2" joint="EEF_JOINT_LB_2" forcerange="-3 3"/>
  </actuator>

  <sensor>
        <actuatorpos name="body_lift" actuator="body_lift"/>
        <actuatorpos name="shoulder_r1" actuator="shoulder_right_axis"/>
        <actuatorpos name="shoulder_r2" actuator="shoulder_right_axis2"/>
        <actuatorpos name="elbow_r" actuator="elbow_right"/>
        <actuatorpos name="shoulder_l1" actuator="shoulder_left_axis"/>
        <actuatorpos name="shoulder_l2" actuator="shoulder_left_axis2"/>
        <actuatorpos name="elbow_l" actuator="elbow_left"/>

        <actuatorpos name="actuator1" actuator="ACTUATOR1_motor"/>
        <actuatorpos name="actuator2" actuator="ACTUATOR2_motor"/>
        <actuatorpos name="actuator3" actuator="ACTUATOR3_motor"/>
        <actuatorpos name="actuator4" actuator="ACTUATOR4_motor"/>
        <actuatorpos name="actuator5" actuator="ACTUATOR5_motor"/>
        <actuatorpos name="actuator6" actuator="ACTUATOR6_motor"/>
        <actuatorpos name="actuator7" actuator="ACTUATOR7_motor"/>
        <actuatorpos name="actuator8" actuator="EEF_JOINT_LB_motor"/>

        <actuatorpos name="actuator9" actuator="ACTUATOR1_motor_2"/>
        <actuatorpos name="actuator10" actuator="ACTUATOR2_motor_2"/>
        <actuatorpos name="actuator11" actuator="ACTUATOR3_motor_2"/>
        <actuatorpos name="actuator12" actuator="ACTUATOR4_motor_2"/>
        <actuatorpos name="actuator13" actuator="ACTUATOR5_motor_2"/>
        <actuatorpos name="actuator14" actuator="ACTUATOR6_motor_2"/>
        <actuatorpos name="actuator15" actuator="ACTUATOR7_motor_2"/>
        <actuatorpos name="actuator16" actuator="EEF_JOINT_LB_motor_2"/>
  </sensor>

  <keyframe>
    <!--
    The values below are split into rows for readibility:
      body lift                                     0       [1]
      leg position                                  1~4     [4]
      right arm position; left arm position         5~10    [6]
      main robot                                    11~21   [11]
      slave robot                                   22~32   [11]

      ctrl
      body lift                                     0       [1]
      arm                                           1~6     [6]
      main robot                                    7~14    [8]
      slave robot                                   15~22   [8]
    -->
    <key name="new_stand_grab" 
         qpos=" 0
                0 0 0 0
                0.60 -0.52 -1.05 0.58 -0.52 -1.05
                4.7124 -2.25 0 2.58 0 -2.1 1.5708 0 0 0 0
                -1.5708 2.25 0 -2.58 0 2.1 1.5708 0 0 0 0 " 
         ctrl=" 1.8
                0.608 -0.625 -1.21 0.68 -0.625 -1.21
                4.7124 -2.25 0 2.58 0 -2.1 1.5708 0
                -1.5708 2.25 0 -2.58 0 2.1 1.5708 0"/>   
    
    <key name="new_stand_holdup" 
         qpos=" 0
                0 0 0 0
                -2.1 1.01 -1.3 -1.84 0.98 -1.3
                4.7124 -2.25 0 2.58 0 -2.1 1.5708 0 0 0 0
                -1.5708 2.25 0 -2.58 0 2.1 1.5708 0 0 0 0 " 
         ctrl=" 1.8
                -2.1 1.01 -1.3 -2.04 1.01 -1.3
                4.7124 -2.25 0 2.58 0 -2.1 1.5708 0
                -1.5708 2.25 0 -2.58 0 2.1 1.5708 0"/>

    <!-- <key name="new_stand_holdup" 
         qpos=" 0
                0 0 0 0
                -2.1 1.01 -1.3 -1.93 0.97 -1.3
                4.7124 -2.25 0 2.58 0 -2.1 1.5708 0 0 0 0
                -1.5708 2.25 0 -2.58 0 2.1 1.5708 0 0 0 0 " 
         ctrl=" 1.8
                -2.1 1.01 -1.3 -2.04 1.01 -1.3
                4.7124 -2.25 0 2.58 0 -2.1 1.5708 0
                -1.5708 2.25 0 -2.58 0 2.1 1.5708 0"/> -->

    <key name="new_stand_holdup2" 
         qpos=" 0
                0 0 0 0
                0.60 -0.52 -1.05 0.209 0.209 0.2
                4.7124 -2.25 0 2.58 0 -2.1 1.5708 0 0 0 0
                -1.5708 2.25 0 -2.58 0 2.1 1.5708 0 0 0 0 " 
         ctrl=" 1.8
                0.608 -0.625 -1.21 0.209 0.209 0.2
                4.7124 -2.25 0 2.58 0 -2.1 1.5708 0
                -1.5708 2.25 0 -2.58 0 2.1 1.5708 0"/>     
    
    <key name="new_down" 
         qpos=" -0.67
                -1.7 -2.8 -1.7 -2.8
                0.60 -0.52 -1.05 0.58 -0.52 -1.05
                4.7124 -2.25 0 2.58 0 -2.1 1.5708 0 0 0 0
                -1.5708 2.25 0 -2.58 0 2.1 1.5708 0 0 0 0 " 
         ctrl=" 0.183
                0.608 -0.625 -1.21 0.68 -0.625 -1.21
                4.7124 -2.25 0 2.58 0 -2.1 1.5708 0
                -1.5708 2.25 0 -2.58 0 2.1 1.5708 0"/>       
    
    <!-- <key name="stand" 
         qpos=" 0
                0 0 0 0
                0 0 0 0 0 0
                3.1416 1.5708 0 -1.5708 0 1.5708 0 0 0 0 0
                0 -1.5708 0 1.5708 0 -1.5708 0 0 0 0 0" 
         ctrl=" 1.8
                0 0 0
                3.1416 1.5708 0 -1.5708 0 1.5708 0 0
                0 -1.5708 0 1.5708 0 -1.5708 0 0"/> 

    <key name="squat_down" 
         qpos=" -0.67
                -1.7 -2.8 -1.7 -2.8
                0.003 -0.028 -0.03 0.003 -0.028 -0.03 
                3.1416 1.5708 0 -1.5708 0 1.5708 0 0 0 0 0
                0 -1.5708 0 1.5708 0 -1.5708 0 0 0 0 0" 
         ctrl=" -0.01
                0 0 0
                3.1416 1.5708 0 -1.5708 0 1.5708 0 0
                0 -1.5708 0 1.5708 0 -1.5708 0 0"/>   -->
    
       
  </keyframe>

</mujoco>
